{"e":"depthUpdate","E":1782785661014,"s":"BTCUSDT","U":96688016974,"u":96688017029,"b":[["59774.00000000","2.05002000"],["59773.08000000","0.56375000"],["59772.00000000","0.02018000"],["59771.61000000","0.08186000"],["59770.16000000","0.00000000"],["59770.15000000","0.08042000"],["59770.01000000","0.00000000"],["59769.80000000","0.00020000"],["59742.00000000","0.02650000"],["59732.69000000","0.01660000"],["59723.01000000","0.00355000"],["59719.25000000","0.01660000"],["59705.81000000","0.01660000"],["59693.67000000","0.00000000"],["59680.24000000","0.00000000"],["59666.81000000","0.00000000"],["59663.20000000","0.00142000"],["59622.57000000","0.00000000"],["59616.58000000","0.01023000"],["53796.60000000","0.00530000"]],"a":[["59774.01000000","0.88280000"],["59774.02000000","0.00089000"],["59776.31000000","0.04777000"],["59776.58000000","0.42036000"],["59776.59000000","0.80190000"],["59776.60000000","0.00009000"],["59777.00000000","0.07237000"],["59778.96000000","0.00029000"],["59778.97000000","0.14018000"],["59781.26000000","0.00000000"],["59781.65000000","0.00913000"],["59782.01000000","0.00400000"],["59787.05000000","0.00000000"],["59787.63000000","0.00409000"]]}
{"e":"depthUpdate","E":1782785661114,"s":"BTCUSDT","U":96688017030,"u":96688017056,"b":[["59774.00000000","2.05246000"],["59773.99000000","0.00035000"],["59771.01000000","0.00837000"],["59769.07000000","0.00000000"],["59750.04000000","0.05428000"],["53796.60000000","0.00509000"]],"a":[["59776.31000000","0.00018000"],["59779.40000000","0.00009000"],["59779.41000000","0.61018000"],["59782.01000000","0.00000000"],["59782.51000000","0.00400000"],["59787.63000000","0.00009000"],["59788.48000000","0.00400000"],["74523.62000000","0.00055000"],["89447.64000000","0.00009000"]]}
{"e":"depthUpdate","E":1782785661214,"s":"BTCUSDT","U":96688017057,"u":96688017095,"b":[["59774.00000000","1.61802000"],["59773.99000000","0.00062000"],["59771.10000000","0.05611000"],["59771.01000000","0.00018000"],["59770.51000000","0.00924000"],["59770.16000000","0.00837000"],["53796.60000000","0.00509000"]],"a":[["59774.01000000","0.88296000"],["59776.00000000","0.01318000"],["59776.30000000","0.00000000"],["59776.31000000","0.00000000"],["59776.58000000","0.27123000"],["59777.00000000","0.07255000"],["59779.40000000","0.00000000"],["59779.41000000","0.61009000"],["59781.69000000","0.00400000"],["59782.51000000","0.00000000"],["60646.01000000","0.12682000"]]}
{"e":"depthUpdate","E":1782785661314,"s":"BTCUSDT","U":96688017096,"u":96688017208,"b":[["59774.00000000","2.05287000"],["59773.99000000","0.00062000"],["59771.10000000","0.05611000"],["59771.01000000","0.00000000"],["59770.51000000","0.00942000"],["59770.16000000","0.00837000"],["59770.01000000","0.00000000"],["59769.80000000","0.00020000"],["59614.11000000","0.10064000"],["59200.00000000","8.46990000"],["57596.89000000","0.00035000"],["53796.60000000","0.00509000"],["50000.00000000","604.02933000"]],"a":[["59774.01000000","0.88043000"],["59774.02000000","0.00089000"],["59776.30000000","0.00009000"],["59776.31000000","0.04971000"],["59776.56000000","0.00009000"],["59776.57000000","0.00009000"],["59778.96000000","0.00029000"],["59778.97000000","0.14027000"],["59779.40000000","0.00009000"],["59781.69000000","0.00000000"],["59782.15000000","0.00400000"],["59787.14000000","0.00000000"],["59787.78000000","0.00400000"],["59788.48000000","0.00000000"],["59900.51000000","0.09912000"],["89628.44000000","0.00037000"]]}
{"e":"depthUpdate","E":1782785661414,"s":"BTCUSDT","U":96688017209,"u":96688017309,"b":[["59774.00000000","1.61892000"],["59773.99000000","0.00098000"],["59770.16000000","0.00009000"],["59770.01000000","0.00009000"],["59769.80000000","0.00029000"],["59769.07000000","0.00837000"],["59767.05000000","0.04693000"],["59763.51000000","0.00000000"],["59732.69000000","0.00000000"],["59719.25000000","0.00000000"],["59691.07000000","0.01660000"],["59677.64000000","0.01660000"],["53796.60000000","0.00509000"],["53796.00000000","0.00010000"],["47819.20000000","0.00000000"]],"a":[["59774.01000000","1.13432000"],["59774.02000000","0.00035000"],["59776.00000000","0.01318000"],["59776.31000000","0.04989000"],["59776.56000000","0.00000000"],["59776.99000000","0.00600000"],["59777.00000000","0.00018000"],["59778.96000000","0.00020000"],["59779.40000000","0.05216000"],["59779.41000000","0.61009000"],["59779.99000000","0.25050000"],["59780.67000000","0.00400000"],["59781.34000000","0.00000000"],["59782.15000000","0.00000000"],["59782.50000000","0.00400000"],["59782.98000000","0.00000000"],["59787.78000000","0.00000000"],["59788.40000000","0.00000000"],["60639.94000000","0.00385000"],["60644.80000000","0.00000000"],["75268.86000000","0.00000000"]]}
{"e":"depthUpdate","E":1782785661514,"s":"BTCUSDT","U":96688017310,"u":96688017365,"b":[["59774.00000000","1.62452000"],["59773.99000000","0.00098000"],["59771.62000000","0.00000000"],["59771.61000000","0.00018000"],["59770.51000000","0.00942000"],["59767.05000000","0.00000000"],["59757.34000000","0.00000000"],["59756.50000000","0.00400000"],["59728.43000000","0.00000000"],["53796.60000000","0.00530000"],["53796.00000000","0.00000000"]],"a":[["59774.01000000","1.49396000"],["59775.16000000","0.00009000"],["59775.17000000","0.02398000"],["59775.18000000","0.06634000"],["59776.30000000","0.00591000"],["59776.59000000","0.80199000"],["59776.99000000","0.00018000"],["59778.17000000","0.06634000"],["59780.04000000","0.00400000"],["59780.67000000","0.00000000"],["59781.16000000","0.04422000"],["59784.15000000","0.04422000"],["59792.07000000","0.00400000"],["59793.97000000","0.00000000"],["60634.54000000","0.00000000"],["60639.86000000","0.00262000"],["60639.94000000","0.00016000"]]}
{"e":"depthUpdate","E":1782785661614,"s":"BTCUSDT","U":96688017366,"u":96688017413,"b":[["59774.00000000","1.59261000"],["59773.10000000","0.02024000"],["59773.09000000","0.00047000"],["59773.08000000","0.56366000"],["59772.00000000","0.01618000"],["59771.61000000","0.00000000"],["59770.15000000","0.08060000"],["59757.11000000","0.00000000"],["59756.50000000","0.00000000"],["59755.72000000","0.00400000"],["59754.28000000","0.58952000"],["59753.72000000","0.41038000"],["59749.50000000","0.00400000"],["53796.60000000","0.00530000"],["53796.00000000","0.00010000"]],"a":[["59774.01000000","1.49415000"],["59775.00000000","0.01027000"],["59775.17000000","0.02416000"],["59775.18000000","0.06652000"],["59776.00000000","0.01318000"],["59776.30000000","0.00609000"],["59776.62000000","0.01021000"],["59776.64000000","0.04087000"],["59776.99000000","0.00000000"],["59780.04000000","0.00000000"],["60634.07000000","0.00000000"],["89643.96000000","0.00043000"]]}
{"e":"depthUpdate","E":1782785661714,"s":"BTCUSDT","U":96688017414,"u":96688017465,"b":[["59774.00000000","1.28928000"],["59773.99000000","0.00098000"],["59773.10000000","0.02024000"],["59773.09000000","0.00029000"],["59771.11000000","0.00029000"],["59770.91000000","0.00157000"],["59770.00000000","0.04732000"],["59769.07000000","0.00000000"],["59769.06000000","0.00000000"],["59768.45000000","0.00009000"],["59768.26000000","0.00029000"],["59767.55000000","0.00837000"],["59756.77000000","0.00000000"],["59754.29000000","0.00020000"],["59742.00000000","0.02659000"],["59728.43000000","0.00000000"],["53796.60000000","0.00509000"],["53796.00000000","0.00010000"],["33000.00000000","36.15385000"]],"a":[["59775.17000000","0.02436000"],["59776.57000000","0.05028000"],["59776.58000000","0.27143000"],["59776.62000000","0.01001000"],["59778.16000000","0.00020000"],["59779.98000000","0.00000000"],["59784.14000000","0.00020000"],["59784.78000000","0.00000000"],["59785.08000000","2.07398000"],["59785.10000000","0.00000000"],["59786.50000000","0.00020000"],["59787.97000000","0.00009000"],["59791.02000000","0.00020000"],["59797.30000000","0.00020000"],["59804.62000000","0.04810000"],["59808.51000000","0.00000000"],["59838.32000000","1.66991000"],["60622.45000000","0.00000000"],["60626.15000000","0.00000000"]]}
{"e":"depthUpdate","E":1782785661814,"s":"BTCUSDT","U":96688017466,"u":96688017513,"b":[["59774.00000000","1.28928000"],["59773.08000000","0.56375000"],["59772.01000000","0.00009000"],["59772.00000000","0.07201000"],["59770.94000000","0.00000000"],["59770.91000000","0.00000000"],["59770.90000000","0.00168000"],["59770.15000000","0.08069000"],["59769.90000000","0.00009000"],["59769.89000000","0.10143000"],["59769.61000000","0.00268000"],["59768.26000000","0.00020000"],["59768.25000000","0.00000000"],["59767.10000000","0.00000000"],["59755.72000000","0.00000000"],["59754.96000000","0.00400000"],["59728.43000000","0.00000000"],["59715.86000000","0.00000000"],["59715.28000000","1.00518000"],["59700.86000000","1.54168000"],["53796.60000000","0.00488000"],["53796.00000000","0.00000000"]],"a":[["59775.61000000","0.00009000"],["59776.31000000","0.04989000"],["59776.50000000","0.00400000"],["59776.57000000","0.05037000"],["59776.58000000","0.27134000"],["59776.59000000","0.80181000"],["59778.17000000","0.06643000"],["59778.61000000","0.05216000"],["59782.09000000","0.42128000"],["59782.99000000","0.62813000"],["59787.98000000","0.00020000"],["59800.50000000","0.00000000"],["60585.42000000","0.00000000"],["65751.41000000","0.00009000"]]}
{"e":"depthUpdate","E":1782785661914,"s":"BTCUSDT","U":96688017514,"u":96688017531,"b":[["59772.01000000","0.00000000"],["59772.00000000","0.01618000"],["59770.00000000","0.04732000"],["59759.53000000","0.00009000"],["53796.60000000","0.00451000"]],"a":[["59783.45000000","0.00009000"],["60584.21000000","0.00000000"],["62033.42000000","0.00032000"],["65751.41000000","0.00000000"],["90453.37000000","0.00029000"]]}
{"e":"depthUpdate","E":1782785662014,"s":"BTCUSDT","U":96688017532,"u":96688017557,"b":[["59774.00000000","1.28928000"],["59771.10000000","0.05611000"],["59770.81000000","0.00000000"],["59770.80000000","0.00000000"],["59748.13000000","0.01660000"],["59734.68000000","0.01660000"],["59721.24000000","0.01660000"],["59715.28000000","0.00000000"],["59715.26000000","1.00518000"],["59705.81000000","0.00000000"],["59691.07000000","0.00000000"],["59677.64000000","0.00000000"],["53796.60000000","0.00451000"]],"a":[["59774.01000000","1.49370000"],["59776.56000000","0.00009000"],["59776.57000000","0.05046000"],["59776.58000000","0.27143000"],["59778.15000000","0.00837000"],["59781.60000000","0.00000000"],["59788.49000000","0.03335000"],["59790.84000000","0.00000000"],["60579.36000000","0.00314000"],["75268.86000000","0.00055000"]]}
{"e":"depthUpdate","E":1782785662114,"s":"BTCUSDT","U":96688017558,"u":96688017569,"b":[["59774.00000000","1.28937000"],["59773.31000000","0.00009000"],["59773.30000000","0.05583000"],["59747.51000000","0.78000000"],["53796.60000000","0.00472000"]],"a":[["59774.01000000","1.49361000"],["59776.60000000","0.00000000"],["59788.16000000","0.00281000"],["59803.12000000","0.00000000"]]}
{"e":"depthUpdate","E":1782785662214,"s":"BTCUSDT","U":96688017570,"u":96688017710,"b":[["59774.00000000","1.30452000"],["59773.99000000","0.00107000"],["59773.30000000","0.05601000"],["59773.09000000","0.00020000"],["59773.08000000","0.01085000"],["59772.96000000","0.00018000"],["59772.01000000","0.00009000"],["59771.34000000","0.00000000"],["59770.90000000","0.00000000"],["59770.50000000","0.00000000"],["59770.16000000","0.00000000"],["59770.15000000","0.00018000"],["59770.00000000","0.04714000"],["59769.90000000","0.00000000"],["59769.89000000","0.00000000"],["59769.80000000","0.00020000"],["59769.79000000","0.00052000"],["59769.61000000","0.00000000"],["59769.00000000","0.00300000"],["59768.53000000","0.00000000"],["59768.45000000","0.13838000"],["59768.19000000","0.00009000"],["59768.08000000","0.00000000"],["59768.03000000","0.00029000"],["59767.90000000","0.00170000"],["59767.55000000","0.00000000"],["59767.04000000","0.00000000"],["59767.01000000","0.28490000"],["59767.00000000","0.00568000"],["59766.94000000","0.08042000"],["59766.27000000","0.00837000"],["59765.34000000","0.00000000"],["59764.13000000","0.80172000"],["59764.09000000","0.00000000"],["59760.92000000","0.80192000"],["59760.91000000","0.00000000"],["59760.90000000","0.00000000"],["59759.78000000","0.00000000"],["59754.96000000","0.00000000"],["59753.71000000","1.10875000"],["59750.04000000","0.00034000"],["59748.13000000","0.00000000"],["59748.00000000","0.02093000"],["59747.51000000","0.00000000"],["59745.04000000","0.60344000"],["59742.00000000","0.03059000"],["59739.00000000","0.00360000"],["59723.01000000","0.00000000"],["59715.26000000","0.00000000"],["59713.66000000","0.00000000"],["59706.72000000","1.00518000"],["59706.46000000","0.01660000"],["59700.87000000","3.34593000"],["59700.86000000","0.00000000"],["59693.69000000","3.34593000"],["59663.20000000","0.00000000"],["53796.60000000","0.00472000"]],"a":[["59774.01000000","1.60547000"],["59774.56000000","0.00000000"],["59774.99000000","0.00000000"],["59775.00000000","0.01427000"],["59775.02000000","0.00034000"],["59775.15000000","0.03963000"],["59775.16000000","0.05216000"],["59775.17000000","0.00038000"],["59775.99000000","0.00000000"],["59776.30000000","0.00018000"],["59776.56000000","0.00000000"],["59776.57000000","0.05037000"],["59776.58000000","0.27134000"],["59781.68000000","0.01675000"],["59784.03000000","0.60305000"],["59786.99000000","0.00000000"],["59789.57000000","0.00000000"],["59790.42000000","0.00400000"],["59791.03000000","0.06644000"],["59791.75000000","0.00000000"],["59792.07000000","0.00000000"],["59798.58000000","0.00000000"],["59799.00000000","0.00309000"],["59802.44000000","1.65789000"],["59822.67000000","1.00518000"],["59827.05000000","0.93594000"],["59828.69000000","0.00000000"],["59832.42000000","0.00000000"],["59880.27000000","0.00000000"],["60579.28000000","0.00000000"],["60579.36000000","0.00000000"]]}
{"e":"depthUpdate","E":1782785662314,"s":"BTCUSDT","U":96688017711,"u":96688017793,"b":[["59774.00000000","1.30452000"],["59773.99000000","0.00098000"],["59773.31000000","0.00000000"],["59773.30000000","0.00018000"],["59773.11000000","0.00000000"],["59773.10000000","0.00018000"],["59773.09000000","0.00029000"],["59773.08000000","0.01085000"],["59772.96000000","0.00000000"],["59771.11000000","0.00020000"],["59771.10000000","0.00027000"],["59770.51000000","0.00942000"],["59770.15000000","0.00000000"],["59770.00000000","0.04732000"],["59768.74000000","0.01050000"],["59768.46000000","0.00009000"],["59767.50000000","0.00000000"],["59767.01000000","0.28490000"],["59766.73000000","0.02007000"],["59765.95000000","0.05216000"],["59765.36000000","0.05216000"],["59764.13000000","0.00000000"],["59764.02000000","0.80192000"],["59760.93000000","0.77423000"],["59754.28000000","0.41311000"],["59753.72000000","0.00000000"],["59750.04000000","0.00000000"],["59749.53000000","0.05352000"],["59749.23000000","0.41041000"],["59745.00000000","0.00801000"],["59724.50000000","0.54263000"],["59723.01000000","0.00355000"],["59699.26000000","0.00000000"],["59663.20000000","0.00142000"],["59614.11000000","0.00000000"],["53796.60000000","0.00472000"],["50000.00000000","604.02933000"]],"a":[["59775.00000000","0.01427000"],["59775.15000000","0.03981000"],["59775.16000000","0.05234000"],["59775.17000000","0.00020000"],["59776.00000000","0.01318000"],["59776.30000000","0.00000000"],["59780.70000000","0.00009000"],["59782.09000000","0.58622000"],["59787.23000000","0.14687000"],["59797.31000000","0.61002000"],["59798.57000000","0.00000000"],["59874.19000000","0.02621000"],["59900.51000000","0.00000000"],["60573.96000000","0.00000000"],["76021.55000000","0.00000000"]]}
{"e":"depthUpdate","E":1782785662414,"s":"BTCUSDT","U":96688017794,"u":96688017855,"b":[["59774.00000000","1.30453000"],["59773.99000000","0.00098000"],["59773.30000000","0.00000000"],["59773.10000000","0.00000000"],["59772.00000000","0.01618000"],["59771.10000000","0.00009000"],["59769.81000000","0.00009000"],["59769.80000000","0.05604000"],["59768.45000000","0.13856000"],["59768.44000000","0.05178000"],["59768.18000000","0.04018000"],["59767.61000000","0.00009000"],["59767.60000000","0.05583000"],["59767.44000000","0.00000000"],["59734.68000000","0.00000000"],["59721.24000000","0.00000000"],["59706.46000000","0.00000000"],["59694.51000000","1.40416000"],["59689.83000000","0.01660000"],["59676.40000000","0.01660000"],["59662.97000000","0.01660000"],["57065.11000000","0.00035000"],["53796.60000000","0.00451000"],["47819.20000000","0.00000000"]],"a":[["59774.01000000","1.60368000"],["59775.02000000","0.00000000"],["60565.58000000","0.00000000"],["60573.49000000","0.00000000"]]}
{"e":"depthUpdate","E":1782785662514,"s":"BTCUSDT","U":96688017856,"u":96688017881,"b":[["59773.12000000","0.00156000"],["59770.00000000","0.04732000"],["59769.80000000","0.05622000"],["59768.18000000","0.04000000"],["59767.00000000","0.00300000"],["59766.94000000","0.00000000"],["59765.53000000","0.00268000"],["59728.42000000","0.00000000"],["59632.17000000","0.00000000"],["53796.60000000","0.00451000"]],"a":[["60561.88000000","0.00000000"]]}
{"e":"depthUpdate","E":1782785662614,"s":"BTCUSDT","U":96688017882,"u":96688017898,"b":[["59768.45000000","0.13856000"],["59768.27000000","0.00000000"],["59768.26000000","0.00020000"],["59750.01000000","0.00065000"],["53796.60000000","0.00451000"],["53796.00000000","0.00000000"]],"a":[["59774.01000000","1.60201000"],["59781.57000000","0.60308000"],["60524.89000000","0.00000000"]]}
{"e":"depthUpdate","E":1782785662714,"s":"BTCUSDT","U":96688017899,"u":96688017943,"b":[["59774.00000000","1.30462000"],["59773.09000000","0.00009000"],["59772.38000000","0.00943000"],["59771.11000000","0.00000000"],["59769.80000000","0.05611000"],["59769.21000000","0.00029000"],["59769.20000000","0.08817000"],["59768.46000000","0.00029000"],["59768.26000000","0.00000000"],["59765.36000000","0.05236000"],["59765.35000000","0.62809000"],["59760.93000000","0.77443000"],["59760.92000000","0.80172000"],["59760.14000000","0.00020000"],["59759.79000000","0.00000000"],["59754.29000000","0.00000000"],["59753.68000000","0.00020000"],["59750.88000000","0.00020000"],["59750.37000000","0.00000000"],["59743.51000000","0.00020000"],["59728.42000000","0.00000000"],["59625.62000000","6.39582000"],["53796.60000000","0.00451000"]],"a":[["59781.56000000","0.00020000"],["59782.08000000","0.00000000"],["59782.98000000","0.00020000"],["59784.14000000","0.00000000"],["59787.23000000","0.00000000"],["59787.61000000","0.00020000"],["59788.80000000","0.00000000"],["59789.34000000","0.00020000"],["59790.41000000","0.14687000"],["59791.02000000","0.00000000"],["59791.74000000","0.00000000"],["59794.48000000","0.00020000"],["59797.30000000","0.00000000"],["59802.43000000","0.00020000"],["60518.84000000","0.00000000"],["60523.68000000","0.00000000"]]}
{"e":"depthUpdate","E":1782785662814,"s":"BTCUSDT","U":96688017944,"u":96688017970,"b":[["59773.08000000","0.01085000"],["59772.38000000","0.00961000"],["59769.80000000","0.05611000"],["59769.20000000","0.08835000"],["59768.45000000","0.13838000"],["59768.44000000","0.05160000"],["59750.01000000","0.00020000"],["59728.42000000","0.00000000"],["59694.28000000","0.00000000"],["59616.58000000","0.00000000"],["59612.66000000","0.01023000"],["54992.08000000","0.00019000"],["53796.60000000","0.00472000"]],"a":[["59873.65000000","0.00000000"],["60518.76000000","0.00000000"]]}
{"e":"depthUpdate","E":1782785662914,"s":"BTCUSDT","U":96688017971,"u":96688018004,"b":[["59774.00000000","1.30462000"],["59769.80000000","0.05620000"],["59769.22000000","0.00009000"],["59769.21000000","0.20949000"],["59768.47000000","0.00009000"],["59768.46000000","0.04833000"],["59768.45000000","0.00009000"],["59767.61000000","0.00000000"],["59767.12000000","0.08319000"],["59767.10000000","0.04851000"],["59764.13000000","0.05216000"],["59759.53000000","0.00009000"],["59694.51000000","1.13980000"],["59685.89000000","0.05697000"],["53796.60000000","0.00472000"]],"a":[["59774.01000000","1.49835000"],["59783.45000000","0.00009000"],["59804.13000000","0.78000000"],["59808.60000000","0.00000000"],["59811.36000000","0.00291000"],["59831.76000000","0.00000000"],["59865.23000000","0.09604000"],["60513.44000000","0.00000000"]]}
{"e":"depthUpdate","E":1782785663014,"s":"BTCUSDT","U":96688018005,"u":96688018025,"b":[["59774.00000000","1.30471000"],["59773.99000000","0.00107000"],["59769.80000000","0.05620000"],["59769.21000000","0.20967000"],["59769.00000000","0.00309000"],["59768.74000000","0.01032000"],["59765.53000000","0.00000000"],["59739.00000000","0.00351000"],["53796.60000000","0.00493000"]],"a":[["60505.07000000","0.00000000"],["60512.97000000","0.00000000"],["62611.49000000","0.00032000"],["76021.55000000","0.00055000"]]}
{"e":"depthUpdate","E":1782785663114,"s":"BTCUSDT","U":96688018026,"u":96688018042,"b":[["59774.00000000","1.30480000"],["59773.99000000","0.00116000"],["59770.57000000","0.00009000"],["59770.56000000","0.08514000"],["59769.21000000","0.20958000"],["59769.20000000","0.00018000"],["59748.13000000","0.01660000"],["59743.50000000","3.34888000"],["59742.00000000","0.02659000"],["59734.68000000","0.01660000"],["59721.24000000","0.01660000"],["59689.83000000","0.00000000"],["59676.40000000","0.00000000"],["59662.97000000","0.00000000"],["59616.58000000","0.01023000"],["59612.66000000","0.00000000"],["53796.60000000","0.00472000"]],"a":[]}
{"e":"depthUpdate","E":1782785663214,"s":"BTCUSDT","U":96688018043,"u":96688018078,"b":[["59774.00000000","1.54394000"],["59772.00000000","0.01618000"],["59770.56000000","0.08532000"],["59769.80000000","0.05611000"],["59769.21000000","0.20958000"],["59769.20000000","0.00000000"],["53796.60000000","0.00472000"]],"a":[["59774.01000000","1.73140000"],["60501.37000000","0.00000000"]]}
{"e":"depthUpdate","E":1782785663314,"s":"BTCUSDT","U":96688018079,"u":96688018090,"b":[["59774.00000000","1.29644000"],["53796.60000000","0.00472000"],["50000.00000000","604.02933000"]],"a":[["59774.01000000","1.73121000"],["59781.01000000","0.00050000"],["59794.48000000","0.00000000"],["59800.02000000","0.00020000"],["76781.76000000","0.00000000"]]}
{"e":"depthUpdate","E":1782785663414,"s":"BTCUSDT","U":96688018091,"u":96688018106,"b":[["59774.00000000","1.29635000"],["59773.99000000","0.00107000"],["59770.57000000","0.00000000"],["59770.56000000","0.00018000"],["59698.89000000","1.54168000"],["54992.08000000","0.00000000"],["53796.60000000","0.00472000"],["47819.20000000","0.00000000"]],"a":[["59786.93000000","0.09197000"],["59795.65000000","0.00000000"]]}
{"e":"depthUpdate","E":1782785663514,"s":"BTCUSDT","U":96688018107,"u":96688018129,"b":[["59774.00000000","1.29626000"],["59772.00000000","0.01618000"],["59770.56000000","0.00000000"],["59768.74000000","0.01050000"],["59728.41000000","0.00000000"],["56538.25000000","0.00035000"],["53796.60000000","0.00493000"]],"a":[["59774.01000000","1.73106000"],["60464.42000000","0.23783000"]]}
{"e":"depthUpdate","E":1782785663614,"s":"BTCUSDT","U":96688018130,"u":96688018146,"b":[["59774.00000000","1.29635000"],["59769.80000000","0.05629000"],["59769.76000000","0.00009000"],["59769.75000000","0.36258000"],["59769.74000000","0.55293000"],["59769.22000000","0.00000000"],["59769.21000000","0.00038000"],["59768.19000000","0.00000000"],["53796.60000000","0.00493000"]],"a":[["60464.42000000","0.00000000"]]}
{"e":"depthUpdate","E":1782785663714,"s":"BTCUSDT","U":96688018147,"u":96688018168,"b":[["59769.80000000","0.05629000"],["59769.75000000","0.36276000"],["59769.74000000","0.55311000"],["59769.21000000","0.00020000"],["59768.74000000","0.01032000"],["59764.13000000","0.00000000"],["59743.04000000","0.78000000"],["59728.41000000","0.00000000"],["53796.60000000","0.00472000"],["53796.00000000","0.00020000"]],"a":[["60463.21000000","0.00000000"]]}
{"e":"depthUpdate","E":1782785663814,"s":"BTCUSDT","U":96688018169,"u":96688018185,"b":[["59769.80000000","0.05620000"],["59769.75000000","0.36296000"],["59769.21000000","0.00000000"],["59768.46000000","0.04813000"],["59768.45000000","0.00029000"],["59768.08000000","0.00268000"],["59751.27000000","0.00020000"],["59750.88000000","0.00000000"],["59728.41000000","0.00000000"],["53796.60000000","0.00472000"],["53796.00000000","0.00000000"],["36000.00000000","38.40038000"]],"a":[]}
{"e":"depthUpdate","E":1782785663914,"s":"BTCUSDT","U":96688018186,"u":96688018195,"b":[["59769.06000000","0.10293000"],["59768.47000000","0.00000000"],["59768.46000000","0.00000000"],["59759.53000000","0.00000000"],["53796.60000000","0.00472000"]],"a":[["59783.45000000","0.00000000"],["60458.38000000","0.00226000"],["76781.76000000","0.00055000"]]}
{"e":"depthUpdate","E":1782785664014,"s":"BTCUSDT","U":96688018196,"u":96688018210,"b":[["59774.00000000","1.29644000"],["59769.74000000","0.55320000"],["59769.07000000","0.00009000"],["59767.10000000","0.00000000"],["59759.53000000","0.00009000"],["53796.60000000","0.00472000"]],"a":[["59783.45000000","0.00009000"],["65192.08000000","0.00000000"]]}
{"e":"depthUpdate","E":1782785664114,"s":"BTCUSDT","U":96688018211,"u":96688018219,"b":[["59767.12000000","0.00277000"],["59300.00000000","2.94401000"],["53796.60000000","0.00493000"]],"a":[["59774.01000000","1.73173000"],["60458.38000000","0.00000000"],["63194.95000000","0.00032000"]]}
{"e":"depthUpdate","E":1782785664214,"s":"BTCUSDT","U":96688018220,"u":96688018229,"b":[["59701.21000000","0.00700000"],["53796.60000000","0.00472000"],["47819.00000000","0.00000000"]],"a":[["59840.71000000","0.46149000"],["59844.65000000","0.00000000"],["65578.66000000","0.00000000"],["77549.58000000","0.00000000"]]}
{"e":"depthUpdate","E":1782785664314,"s":"BTCUSDT","U":96688018230,"u":96688018247,"b":[["59748.13000000","0.00000000"],["59734.68000000","0.00000000"],["59721.24000000","0.00000000"],["59703.19000000","0.01660000"],["59689.76000000","0.01660000"],["59676.32000000","0.01660000"],["53796.60000000","0.00472000"],["50000.00000000","604.02933000"]],"a":[["59774.01000000","1.72337000"],["59781.68000000","0.00000000"],["59786.29000000","0.01675000"],["59842.37000000","0.02188000"],["60458.30000000","0.00000000"],["66385.25000000","0.00000000"]]}
{"e":"depthUpdate","E":1782785664414,"s":"BTCUSDT","U":96688018248,"u":96688018256,"b":[["53796.60000000","0.00451000"],["47819.20000000","0.00020000"]],"a":[["59787.61000000","0.00000000"],["59790.64000000","0.34325000"],["60452.98000000","0.00000000"]]}
{"e":"depthUpdate","E":1782785664514,"s":"BTCUSDT","U":96688018257,"u":96688018271,"b":[["59728.41000000","0.00000000"],["53796.60000000","0.00451000"],["47819.20000000","0.00000000"]],"a":[["59774.30000000","0.00936000"],["59777.29000000","0.00898000"],["60452.51000000","0.00000000"],["66829.09000000","0.00000000"]]}
{"e":"depthUpdate","E":1782785664614,"s":"BTCUSDT","U":96688018272,"u":96688018296,"b":[["59774.00000000","1.29653000"],["59770.33000000","0.00009000"],["59770.32000000","0.10464000"],["59769.74000000","0.55311000"],["59769.07000000","0.00000000"],["59769.06000000","0.00000000"],["59750.01000000","0.00061000"],["59703.19000000","0.00000000"],["59667.61000000","0.01660000"],["56016.25000000","0.00036000"],["53796.60000000","0.00451000"]],"a":[["59774.01000000","1.72815000"],["59774.30000000","0.00000000"],["59776.58000000","0.27116000"],["59779.43000000","0.04449000"],["60440.92000000","0.00000000"],["60444.62000000","0.00000000"]]}
{"e":"depthUpdate","E":1782785664714,"s":"BTCUSDT","U":96688018297,"u":96688018331,"b":[["59774.00000000","1.54402000"],["59773.99000000","0.00116000"],["59773.09000000","0.00000000"],["59773.08000000","0.00063000"],["59772.38000000","0.00018000"],["59771.06000000","0.00009000"],["59771.05000000","0.55292000"],["59770.51000000","0.00942000"],["59770.32000000","0.10482000"],["59769.80000000","0.05611000"],["59769.75000000","0.16000000"],["59769.74000000","0.00000000"],["59728.40000000","0.00000000"],["53796.60000000","0.00451000"]],"a":[["59777.29000000","0.00000000"],["59781.57000000","0.00000000"],["59794.22000000","0.45833000"],["59796.62000000","0.60292000"],["78028.64000000","0.00000000"]]}
{"e":"depthUpdate","E":1782785664814,"s":"BTCUSDT","U":96688018332,"u":96688018373,"b":[["59774.00000000","1.54385000"],["59773.99000000","0.00107000"],["59773.08000000","0.00045000"],["59772.38000000","0.00000000"],["59772.00000000","0.01618000"],["59771.06000000","0.00029000"],["59771.05000000","0.55310000"],["59770.33000000","0.00029000"],["59769.76000000","0.00029000"],["59769.75000000","0.15980000"],["59768.74000000","0.01050000"],["59768.45000000","0.00009000"],["59743.51000000","0.00000000"],["59728.40000000","0.00000000"],["53796.60000000","0.00472000"],["53796.00000000","0.00020000"]],"a":[["59778.17000000","0.06634000"],["59778.61000000","0.00000000"],["78291.80000000","0.00000000"]]}
{"e":"depthUpdate","E":1782785664914,"s":"BTCUSDT","U":96688018374,"u":96688018379,"b":[["53796.60000000","0.00472000"],["53796.00000000","0.00000000"]],"a":[["77549.58000000","0.00055000"]]}
{"e":"depthUpdate","E":1782785665014,"s":"BTCUSDT","U":96688018380,"u":96688018391,"b":[["59773.02000000","0.00009000"],["59773.01000000","0.01012000"],["59759.53000000","0.00009000"],["53796.60000000","0.00472000"]],"a":[["59783.45000000","0.00009000"],["59838.94000000","0.39771000"],["59839.21000000","0.05746000"],["78827.63000000","0.00000000"]]}
{"e":"depthUpdate","E":1782785665114,"s":"BTCUSDT","U":96688018392,"u":96688018412,"b":[["59774.00000000","1.54421000"],["59773.99000000","0.00116000"],["59773.01000000","0.01030000"],["59768.74000000","0.01032000"],["59768.37000000","0.00009000"],["59768.36000000","0.08042000"],["53796.60000000","0.00451000"]],"a":[["59779.01000000","0.00018000"],["59780.01000000","0.00000000"],["59899.05000000","0.07422000"],["59958.95000000","0.09586000"],["79187.17000000","0.00071000"]]}
{"e":"depthUpdate","E":1782785665214,"s":"BTCUSDT","U":96688018413,"u":96688018419,"b":[["53796.60000000","0.00451000"]],"a":[["59774.01000000","1.72767000"],["63783.85000000","0.00031000"],["78325.08000000","0.00000000"]]}
{"e":"depthUpdate","E":1782785665314,"s":"BTCUSDT","U":96688018420,"u":96688018464,"b":[["59774.00000000","1.54439000"],["59773.99000000","0.00116000"],["59771.69000000","0.00009000"],["59771.68000000","0.11066000"],["59771.10000000","0.00000000"],["59770.33000000","0.00020000"],["59770.32000000","0.00018000"],["59769.18000000","0.00268000"],["59768.45000000","0.00000000"],["59768.37000000","0.00000000"],["59768.08000000","0.00000000"],["59768.03000000","0.00020000"],["59767.12000000","0.00009000"],["53796.60000000","0.00451000"],["50000.00000000","604.02933000"]],"a":[["59774.01000000","1.72448000"],["59774.99000000","0.00009000"],["59775.14000000","0.00009000"],["59775.15000000","0.02427000"],["59775.16000000","0.00018000"],["59775.17000000","0.00029000"],["59775.99000000","0.00009000"],["59776.30000000","0.00009000"],["59776.56000000","0.00009000"],["59776.57000000","0.05046000"],["59776.58000000","0.27125000"],["60018.91000000","0.12381000"],["65500.00000000","12.92895000"],["70000.00000000","95.39469000"],["79225.75000000","0.00000000"]]}
{"e":"depthUpdate","E":1782785665414,"s":"BTCUSDT","U":96688018465,"u":96688018697,"b":[["59774.00000000","2.01170000"],["59773.99000000","0.00062000"],["59773.41000000","0.00009000"],["59773.40000000","0.08021000"],["59773.08000000","0.00036000"],["59773.02000000","0.00000000"],["59772.29000000","0.20599000"],["59772.28000000","0.00009000"],["59772.01000000","0.00000000"],["59772.00000000","0.01618000"],["59771.70000000","0.05173000"],["59771.69000000","0.00009000"],["59771.68000000","0.00018000"],["59771.06000000","0.00020000"],["59771.05000000","0.00018000"],["59770.51000000","0.00942000"],["59770.32000000","0.00000000"],["59770.19000000","0.00268000"],["59770.01000000","0.00000000"],["59769.81000000","0.00000000"],["59769.76000000","0.00020000"],["59769.40000000","0.04707000"],["59768.45000000","0.05217000"],["59768.36000000","0.00000000"],["59767.90000000","0.00000000"],["59767.50000000","0.00400000"],["59767.10000000","0.05217000"],["59767.01000000","1.25191000"],["59765.95000000","0.00000000"],["59765.46000000","0.00000000"],["59765.37000000","3.34593000"],["59765.36000000","0.00020000"],["59764.13000000","0.00000000"],["59760.93000000","0.72956000"],["59759.51000000","0.60330000"],["59756.48000000","0.00444000"],["59753.71000000","1.10475000"],["59748.25000000","0.00000000"],["59745.04000000","0.00000000"],["59743.50000000","3.34488000"],["53796.60000000","0.00472000"],["53796.00000000","0.00010000"],["47819.20000000","0.00000000"]],"a":[["59774.01000000","1.02529000"],["59774.02000000","0.00089000"],["59774.99000000","0.00009000"],["59775.14000000","0.00029000"],["59775.15000000","0.02427000"],["59775.16000000","0.00000000"],["59776.30000000","0.00000000"],["59776.31000000","0.00018000"],["59776.56000000","0.00000000"],["59776.57000000","0.00609000"],["59776.58000000","0.27143000"],["59776.62000000","0.00000000"],["59778.15000000","0.00000000"],["59778.16000000","0.00009000"],["59778.96000000","0.00029000"],["59778.97000000","0.14018000"],["59779.36000000","0.00000000"],["59779.40000000","0.00009000"],["59779.98000000","0.00020000"],["59781.56000000","0.00000000"],["59781.84000000","0.00020000"],["59781.89000000","0.00837000"],["59784.02000000","0.34296000"],["59784.03000000","0.00000000"],["59785.08000000","1.09520000"],["59785.09000000","0.02800000"],["59786.12000000","0.00020000"],["59789.34000000","0.00000000"],["59790.42000000","0.00000000"],["59790.60000000","0.00020000"],["59790.64000000","0.34305000"],["59791.95000000","0.00000000"],["59794.21000000","0.14356000"],["59794.36000000","0.00400000"],["59796.61000000","0.00020000"],["59798.98000000","0.60290000"],["59800.02000000","0.00000000"],["59803.13000000","0.00000000"],["59803.14000000","1.67589000"],["59811.74000000","0.00000000"],["59822.67000000","0.00000000"],["59823.50000000","1.00518000"],["59838.31000000","3.34593000"],["59838.94000000","0.27689000"],["59840.71000000","0.00000000"],["59842.68000000","0.46149000"],["60078.93000000","0.15990000"]]}
{"e":"depthUpdate","E":1782785665514,"s":"BTCUSDT","U":96688018698,"u":96688018873,"b":[["59774.00000000","2.01251000"],["59773.99000000","0.00098000"],["59773.42000000","0.00009000"],["59773.41000000","0.03967000"],["59773.40000000","0.08048000"],["59773.01000000","0.01030000"],["59772.30000000","0.00000000"],["59772.29000000","0.00018000"],["59772.01000000","0.00009000"],["59772.00000000","0.01618000"],["59771.71000000","0.00000000"],["59771.70000000","0.00018000"],["59771.68000000","0.00000000"],["59771.05000000","0.00000000"],["59770.56000000","0.00009000"],["59770.55000000","0.04717000"],["59769.75000000","0.15962000"],["59767.02000000","0.85409000"],["59749.01000000","0.00000000"],["59748.51000000","0.32991000"],["59728.40000000","0.00000000"],["59711.26000000","0.01660000"],["59685.89000000","0.00000000"],["59667.61000000","0.00000000"],["59524.48000000","0.00000000"],["53796.60000000","0.00493000"],["53796.00000000","0.00000000"],["47819.20000000","0.00000000"]],"a":[["59774.01000000","1.02205000"],["59774.02000000","0.00035000"],["59776.00000000","0.01318000"],["59776.31000000","0.00000000"],["59776.59000000","0.80199000"],["59782.09000000","1.48626000"],["59784.78000000","3.34593000"],["59788.16000000","0.00000000"],["59798.00000000","0.01881000"],["59823.50000000","0.00000000"],["59823.51000000","1.00518000"],["59838.31000000","0.00000000"],["59865.23000000","0.00000000"],["59882.34000000","0.03641000"],["59899.25000000","0.00000000"],["79666.01000000","0.00000000"]]}
{"e":"depthUpdate","E":1782785665614,"s":"BTCUSDT","U":96688018874,"u":96688018952,"b":[["59774.00000000","1.57621000"],["59773.99000000","0.00107000"],["59773.58000000","0.00009000"],["59773.57000000","0.21882000"],["59773.56000000","0.55289000"],["59773.42000000","0.00000000"],["59773.41000000","0.00027000"],["59773.40000000","0.08030000"],["59773.01000000","0.01030000"],["59772.29000000","0.00000000"],["59772.28000000","0.00000000"],["59772.01000000","0.00000000"],["59772.00000000","0.01618000"],["59771.70000000","0.00000000"],["59770.55000000","0.04735000"],["59761.78000000","0.60328000"],["59748.51000000","0.08159000"],["59711.26000000","0.00000000"],["59694.28000000","0.05194000"],["59677.97000000","0.01660000"],["59556.19000000","0.02621000"],["53796.60000000","0.00493000"],["53796.00000000","0.00010000"],["47819.00000000","0.00000000"]],"a":[["59774.01000000","1.26936000"],["59775.18000000","0.06670000"],["59775.61000000","0.00591000"],["59776.54000000","0.00009000"],["59776.55000000","0.33289000"],["59776.56000000","0.80172000"],["59776.57000000","0.00018000"],["59776.58000000","0.00047000"],["59776.59000000","0.00027000"],["59779.40000000","0.00000000"],["59823.51000000","0.00000000"],["59823.53000000","1.00518000"],["59873.65000000","0.09554000"],["80159.53000000","0.00000000"]]}
{"e":"depthUpdate","E":1782785665714,"s":"BTCUSDT","U":96688018953,"u":96688018994,"b":[["59774.00000000","1.57621000"],["59773.57000000","0.21900000"],["59773.56000000","0.55307000"],["59773.41000000","0.00009000"],["59769.80000000","0.05593000"],["59728.40000000","0.00000000"],["59622.57000000","0.01023000"],["59616.58000000","0.00000000"],["55499.06000000","0.00036000"],["53796.60000000","0.00472000"],["53796.00000000","0.00000000"]],"a":[["59774.01000000","1.26927000"],["59775.18000000","0.06670000"],["59775.61000000","0.00609000"],["59776.00000000","0.01318000"],["59776.55000000","0.33307000"],["59776.56000000","0.80190000"],["59776.57000000","0.00000000"],["59776.58000000","0.00029000"],["59776.59000000","0.00009000"],["60139.01000000","0.20653000"]]}
{"e":"depthUpdate","E":1782785665814,"s":"BTCUSDT","U":96688018995,"u":96688019070,"b":[["59774.00000000","2.01025000"],["59773.99000000","0.00080000"],["59773.57000000","0.21920000"],["59772.00000000","0.01627000"],["59771.06000000","0.00000000"],["59770.56000000","0.00020000"],["59770.55000000","0.00018000"],["59770.33000000","0.00000000"],["59770.01000000","0.00000000"],["59769.18000000","0.00000000"],["59765.38000000","0.00020000"],["59765.36000000","0.00000000"],["59761.79000000","0.00020000"],["59760.93000000","0.72936000"],["59760.53000000","0.00020000"],["59760.14000000","0.00000000"],["59759.52000000","0.00020000"],["59753.68000000","0.00000000"],["59751.27000000","0.00000000"],["59750.37000000","0.00020000"],["59742.00000000","0.02650000"],["59728.40000000","0.00000000"],["59726.03000000","0.00010000"],["53796.60000000","0.00472000"]],"a":[["59774.01000000","1.01786000"],["59774.02000000","0.00089000"],["59779.40000000","0.00009000"],["59782.16000000","0.01675000"],["59786.29000000","0.00000000"],["59797.31000000","0.75568000"],["59823.53000000","0.00000000"],["59824.42000000","1.00518000"],["60199.15000000","0.26674000"],["78325.08000000","0.00055000"],["81350.56000000","0.00000000"]]}
{"e":"depthUpdate","E":1782785665914,"s":"BTCUSDT","U":96688019071,"u":96688019178,"b":[["59774.00000000","2.00935000"],["59773.99000000","0.00035000"],["59773.41000000","0.00000000"],["59773.40000000","0.00018000"],["59772.00000000","0.01627000"],["59771.69000000","0.00000000"],["59771.08000000","0.00268000"],["59770.55000000","0.00000000"],["59770.19000000","0.00000000"],["59769.80000000","0.05611000"],["59769.75000000","0.15971000"],["59769.00000000","0.00709000"],["59764.09000000","0.00400000"],["59745.00000000","0.00401000"],["59731.38000000","0.01660000"],["59726.03000000","0.00021000"],["59717.94000000","0.01753000"],["59704.50000000","0.01660000"],["59689.76000000","0.00000000"],["59677.97000000","0.00000000"],["59676.32000000","0.00000000"],["53796.60000000","0.00472000"]],"a":[["59774.01000000","0.93529000"],["59774.02000000","0.00089000"],["59775.00000000","0.01418000"],["59775.61000000","0.00027000"],["59776.49000000","0.00582000"],["59780.50000000","0.00000000"],["59781.66000000","0.00400000"],["59788.01000000","0.01429000"],["59790.41000000","0.00000000"],["59794.17000000","0.14687000"],["59821.27000000","0.00000000"],["60259.35000000","0.34451000"]]}
{"e":"depthUpdate","E":1782785666014,"s":"BTCUSDT","U":96688019179,"u":96688019352,"b":[["59774.00000000","5.37793000"],["59773.58000000","0.00000000"],["59773.57000000","0.21911000"],["59773.56000000","0.55316000"],["59773.40000000","0.00000000"],["59772.62000000","0.00000000"],["59772.01000000","0.00837000"],["59771.95000000","0.00000000"],["59771.70000000","0.00000000"],["59771.08000000","0.00000000"],["59770.55000000","0.00000000"],["59770.50000000","0.00400000"],["59769.75000000","0.15989000"],["59769.40000000","0.00000000"],["59769.20000000","3.34593000"],["59768.45000000","0.00000000"],["59767.10000000","0.00000000"],["59767.02000000","0.80192000"],["59766.73000000","0.00000000"],["59766.27000000","0.00000000"],["59766.14000000","0.00400000"],["59764.26000000","0.60325000"],["59764.09000000","0.00000000"],["59761.62000000","0.41032000"],["59760.23000000","0.00400000"],["59759.53000000","0.00009000"],["59756.48000000","0.00044000"],["59750.86000000","0.00000000"],["59749.23000000","0.00000000"],["59746.50000000","0.00000000"],["59731.38000000","0.00000000"],["59717.94000000","0.00093000"],["59715.22000000","1.00524000"],["59706.72000000","0.00000000"],["59700.87000000","0.00000000"],["59697.82000000","0.01660000"],["59693.69000000","0.00000000"],["59684.39000000","0.01660000"],["53796.60000000","0.00472000"],["53796.00000000","0.00000000"],["47819.00000000","0.00000000"]],"a":[["59774.01000000","0.32863000"],["59774.02000000","0.00089000"],["59775.00000000","0.01018000"],["59775.15000000","0.00018000"],["59775.18000000","0.06670000"],["59775.61000000","0.00009000"],["59776.00000000","0.01318000"],["59776.49000000","0.00018000"],["59776.50000000","0.00000000"],["59776.54000000","0.00009000"],["59776.55000000","0.09177000"],["59776.56000000","0.00018000"],["59776.63000000","0.00009000"],["59777.00000000","0.00009000"],["59777.24000000","0.00009000"],["59777.99000000","0.00591000"],["59778.00000000","0.01700000"],["59778.97000000","0.14009000"],["59779.39000000","0.62777000"],["59779.40000000","0.00000000"],["59779.41000000","0.00020000"],["59779.42000000","0.00000000"],["59779.45000000","0.00000000"],["59779.99000000","0.25050000"],["59781.01000000","0.00016000"],["59781.66000000","0.00000000"],["59781.84000000","0.00020000"],["59781.85000000","0.00000000"],["59781.89000000","0.00000000"],["59782.08000000","0.80172000"],["59782.09000000","0.58622000"],["59782.16000000","0.00000000"],["59782.40000000","0.00000000"],["59782.73000000","0.00000000"],["59782.99000000","0.00000000"],["59783.30000000","0.00837000"],["59783.45000000","0.00009000"],["59783.71000000","0.00000000"],["59784.02000000","0.00000000"],["59784.08000000","0.00400000"],["59784.78000000","0.00000000"],["59785.11000000","1.68297000"],["59785.97000000","0.24760000"],["59786.51000000","0.00000000"],["59787.98000000","0.62825000"],["59788.01000000","0.01029000"],["59789.68000000","0.00409000"],["59790.62000000","0.00000000"],["59794.17000000","0.00000000"],["59794.36000000","0.00000000"],["59795.66000000","0.00400000"],["59799.66000000","0.14687000"],["59800.50000000","0.00400000"],["59801.41000000","0.60288000"],["59804.13000000","0.00000000"],["59805.00000000","0.00718000"],["59824.42000000","0.00000000"],["59838.31000000","3.34593000"],["59841.59000000","0.00000000"],["59842.68000000","0.00000000"],["59846.38000000","3.34593000"],["59860.11000000","0.00000000"],["60319.61000000","0.44500000"],["81516.22000000","0.00000000"]]}
{"e":"depthUpdate","E":1782785666114,"s":"BTCUSDT","U":96688019353,"u":96688019477,"b":[["59774.00000000","5.66623000"],["59773.99000000","0.00051000"],["59773.56000000","0.55307000"],["59773.50000000","0.00400000"],["59773.01000000","0.01030000"],["59772.01000000","0.00855000"],["59772.00000000","0.02027000"],["59769.80000000","0.00027000"],["59769.75000000","1.13814000"],["59767.60000000","0.00000000"],["59767.01000000","1.37546000"],["59762.04000000","0.17606000"],["59749.50000000","0.00000000"],["59748.00000000","0.01693000"],["59732.88000000","0.01660000"],["59694.51000000","0.44533000"],["59684.39000000","0.00000000"],["53796.60000000","0.00472000"],["33000.00000000","36.15445000"]],"a":[["59774.01000000","0.91039000"],["59774.02000000","0.00089000"],["59774.04000000","0.00000000"],["59775.00000000","0.01018000"],["59775.14000000","0.00020000"],["59775.15000000","0.00000000"],["59775.17000000","0.02512000"],["59775.18000000","0.06670000"],["59775.94000000","0.00268000"],["59776.00000000","0.01318000"],["59776.18000000","0.00009000"],["59776.19000000","0.08042000"],["59776.49000000","0.00000000"],["59776.55000000","0.09177000"],["59776.56000000","0.00000000"],["59776.64000000","0.04105000"],["59777.25000000","0.02024000"],["59777.99000000","0.00018000"],["59778.00000000","0.01300000"],["59778.96000000","0.00611000"],["59778.97000000","0.14018000"],["59779.38000000","0.00009000"],["59779.39000000","0.12676000"],["59780.65000000","0.00450000"],["59781.00000000","0.00700000"],["59781.59000000","0.00034000"],["59782.07000000","0.51558000"],["59782.09000000","0.00000000"],["59784.08000000","0.00000000"],["59784.48000000","0.00400000"],["59784.78000000","0.05217000"],["59789.68000000","0.00009000"],["59790.46000000","0.00400000"],["59790.60000000","3.34613000"],["59790.61000000","0.00020000"],["59795.67000000","3.34593000"],["59798.00000000","0.01600000"],["59799.00000000","0.00709000"],["59813.79000000","0.00281000"],["59838.31000000","0.00000000"],["59845.14000000","0.00000000"],["59846.38000000","0.00000000"],["79108.33000000","0.00021000"],["85169.27000000","0.00091000"]]}
{"e":"depthUpdate","E":1782785666214,"s":"BTCUSDT","U":96688019478,"u":96688019534,"b":[["59774.00000000","5.66623000"],["59773.56000000","0.55325000"],["59772.80000000","0.05592000"],["59770.30000000","0.00000000"],["59770.00000000","0.04732000"],["59769.80000000","0.00009000"],["59769.76000000","0.80192000"],["59769.75000000","1.13832000"],["53796.60000000","0.00493000"],["33000.00000000","36.15385000"]],"a":[["59774.01000000","0.91067000"],["59774.02000000","0.00098000"],["59775.00000000","0.01018000"],["59775.16000000","0.00009000"],["59775.17000000","0.02530000"],["59775.94000000","0.00000000"],["59776.00000000","0.01318000"],["59776.19000000","0.00018000"],["59777.25000000","0.02006000"],["59777.99000000","0.00000000"],["59778.00000000","0.01300000"],["59778.18000000","0.00000000"],["59778.35000000","0.01048000"],["59779.21000000","0.00000000"],["59779.38000000","0.00000000"],["59779.55000000","0.00940000"],["59781.00000000","0.00700000"],["59794.20000000","0.80172000"],["59808.00000000","0.01609000"],["59809.23000000","0.00000000"],["59831.18000000","1.00514000"],["60019.50000000","0.00000000"]]}
{"e":"depthUpdate","E":1782785666314,"s":"BTCUSDT","U":96688019535,"u":96688019983,"b":[["59774.99000000","7.49983000"],["59774.98000000","0.00035000"],["59774.97000000","0.00017000"],["59774.85000000","0.00000000"],["59774.03000000","2.15523000"],["59774.02000000","0.00000000"],["59774.01000000","0.55309000"],["59774.00000000","3.80691000"],["59773.99000000","0.00016000"],["59773.98000000","0.00000000"],["59773.57000000","0.00018000"],["59773.56000000","0.00036000"],["59773.01000000","0.01030000"],["59772.81000000","0.02951000"],["59772.80000000","0.05601000"],["59772.01000000","0.00018000"],["59771.10000000","0.05585000"],["59771.07000000","0.00000000"],["59770.74000000","0.00009000"],["59770.56000000","0.00000000"],["59770.51000000","0.63748000"],["59770.01000000","0.00020000"],["59770.00000000","0.04714000"],["59769.79000000","0.00043000"],["59769.76000000","0.80172000"],["59769.75000000","1.22790000"],["59769.21000000","0.00020000"],["59768.91000000","0.00000000"],["59768.44000000","0.00000000"],["59768.03000000","0.00000000"],["59767.96000000","0.00020000"],["59767.95000000","0.00400000"],["59766.14000000","0.00000000"],["59766.03000000","0.34296000"],["59765.45000000","0.00000000"],["59765.35000000","0.00000000"],["59764.12000000","0.00000000"],["59762.46000000","0.00000000"],["59762.04000000","0.00300000"],["59761.79000000","0.00000000"],["59760.53000000","0.00000000"],["59760.21000000","0.00000000"],["59759.47000000","0.00000000"],["59758.72000000","0.34296000"],["59758.45000000","0.00000000"],["59757.75000000","0.00000000"],["59754.60000000","0.20035000"],["59753.67000000","0.00000000"],["59753.30000000","0.60336000"],["59752.81000000","0.02000000"],["59750.37000000","0.00000000"],["59747.83000000","0.00020000"],["59747.82000000","1.65941000"],["59746.63000000","0.00000000"],["59745.00000000","0.00392000"],["59743.51000000","0.00020000"],["59737.20000000","0.00000000"],["59736.92000000","0.01660000"],["59736.54000000","1.85896000"],["59724.50000000","0.18043000"],["59723.96000000","0.00000000"],["59707.82000000","0.00000000"],["59707.81000000","0.00000000"],["59699.90000000","0.00000000"],["59697.82000000","0.00000000"],["59690.33000000","0.00000000"],["59574.71000000","0.00000000"],["59549.36000000","0.00259000"],["53797.50000000","0.00042000"],["53796.60000000","0.00010000"],["50000.00000000","604.02933000"]],"a":[["59774.01000000","0.00000000"],["59774.02000000","0.00000000"],["59774.03000000","0.00000000"],["59774.99000000","0.00000000"],["59775.00000000","0.18348000"],["59775.01000000","0.00090000"],["59775.14000000","0.00000000"],["59775.16000000","0.00000000"],["59775.17000000","0.00018000"],["59775.18000000","0.00027000"],["59775.98000000","0.00029000"],["59775.99000000","0.06269000"],["59776.00000000","0.01318000"],["59776.18000000","0.00000000"],["59776.19000000","0.00000000"],["59776.54000000","0.00000000"],["59776.55000000","0.00018000"],["59776.58000000","0.00000000"],["59776.59000000","0.00000000"],["59776.63000000","0.00000000"],["59776.64000000","0.00018000"],["59777.24000000","0.00029000"],["59777.25000000","0.02024000"],["59777.99000000","0.00009000"],["59778.00000000","0.01318000"],["59778.16000000","0.00000000"],["59778.17000000","0.00000000"],["59778.96000000","0.00029000"],["59779.38000000","0.00029000"],["59779.39000000","0.28092000"],["59779.41000000","0.00000000"],["59779.42000000","0.00009000"],["59779.50000000","0.00000000"],["59779.98000000","0.00582000"],["59779.99000000","0.00300000"],["59780.37000000","0.00029000"],["59780.38000000","0.04087000"],["59780.58000000","0.00000000"],["59781.16000000","0.00000000"],["59781.46000000","0.00000000"],["59781.84000000","0.00000000"],["59782.04000000","0.00020000"],["59782.05000000","0.80172000"],["59782.06000000","0.00000000"],["59782.07000000","0.00000000"],["59782.08000000","0.00000000"],["59782.45000000","0.00009000"],["59782.98000000","0.00000000"],["59783.30000000","0.00000000"],["59783.99000000","0.00020000"],["59784.15000000","0.00000000"],["59784.20000000","0.05217000"],["59784.48000000","0.00000000"],["59784.77000000","0.05217000"],["59784.78000000","0.24329000"],["59785.08000000","0.00000000"],["59785.11000000","0.00000000"],["59785.32000000","0.00000000"],["59785.53000000","0.00000000"],["59785.96000000","0.43731000"],["59786.12000000","0.00000000"],["59786.29000000","0.00837000"],["59786.50000000","0.00000000"],["59786.87000000","0.00400000"],["59786.92000000","0.00020000"],["59787.98000000","0.00020000"],["59788.48000000","0.00020000"],["59789.35000000","0.00000000"],["59789.95000000","0.05180000"],["59789.99000000","0.62807000"],["59790.46000000","0.00000000"],["59790.59000000","0.00020000"],["59790.60000000","3.34593000"],["59790.61000000","0.00000000"],["59791.30000000","0.00000000"],["59791.39000000","0.00020000"],["59791.70000000","0.00000000"],["59791.92000000","0.60297000"],["59792.20000000","0.00400000"],["59792.28000000","0.00000000"],["59793.17000000","0.00000000"],["59794.19000000","0.00020000"],["59794.21000000","0.00000000"],["59794.43000000","0.00000000"],["59795.66000000","0.00020000"],["59796.61000000","0.00000000"],["59797.28000000","0.00000000"],["59798.82000000","0.00400000"],["59802.00000000","0.02009000"],["59802.43000000","0.00000000"],["59802.44000000","0.00000000"],["59803.14000000","1.67569000"],["59804.00000000","0.01600000"],["59805.00000000","0.01718000"],["59806.63000000","0.04600000"],["59815.10000000","0.00000000"],["59821.35000000","0.00017000"],["59831.18000000","0.00000000"],["59831.67000000","0.00000000"],["59832.25000000","1.00514000"],["59850.82000000","0.00919000"],["59892.45000000","0.00000000"],["59940.39000000","0.00000000"],["60015.51000000","5.00608000"],["60143.27000000","0.00009000"],["60157.29000000","0.00250000"],["64378.23000000","0.00031000"],["85906.06000000","0.00000000"]]}
{"e":"depthUpdate","E":1782785666414,"s":"BTCUSDT","U":96688019984,"u":96688020114,"b":[["59774.99000000","7.49992000"],["59774.07000000","2.19227000"],["59774.06000000","0.00000000"],["59774.05000000","0.00000000"],["59774.04000000","0.80172000"],["59774.03000000","0.00018000"],["59774.01000000","0.55327000"],["59774.00000000","3.55918000"],["59773.57000000","0.00000000"],["59773.56000000","0.00018000"],["59773.01000000","0.01030000"],["59772.81000000","0.02969000"],["59772.80000000","0.00027000"],["59772.01000000","0.00000000"],["59772.00000000","0.02027000"],["59771.10000000","0.00027000"],["59770.51000000","0.63739000"],["59770.17000000","0.05411000"],["59767.18000000","0.05411000"],["59764.19000000","0.03607000"],["59761.20000000","0.03608000"],["59750.01000000","0.00020000"],["59745.00000000","0.01392000"],["59744.00000000","0.01651000"],["59726.03000000","0.00010000"],["53797.50000000","0.00063000"],["53797.00000000","0.00010000"]],"a":[["59775.00000000","0.61956000"],["59775.01000000","0.00090000"],["59775.17000000","0.00000000"],["59775.18000000","0.00000000"],["59775.99000000","0.06296000"],["59776.00000000","0.01318000"],["59776.16000000","0.00009000"],["59776.17000000","0.06633000"],["59776.55000000","0.00000000"],["59776.64000000","0.00000000"],["59776.96000000","0.00268000"],["59777.99000000","0.00000000"],["59778.00000000","0.01318000"],["59778.35000000","0.01066000"],["59778.97000000","0.14036000"],["59779.15000000","0.00009000"],["59779.16000000","0.06633000"],["59781.00000000","0.00709000"],["59781.90000000","0.05227000"],["59782.03000000","0.00009000"],["59782.04000000","0.05211000"],["59782.15000000","0.04422000"],["59785.14000000","0.04422000"],["59785.51000000","0.00400000"],["59786.87000000","0.00000000"],["59789.95000000","0.00000000"],["59790.59000000","1.34167000"],["59863.02000000","0.00000000"],["60091.01000000","0.00000000"]]}
{"e":"depthUpdate","E":1782785666514,"s":"BTCUSDT","U":96688020115,"u":96688020172,"b":[["59774.99000000","7.49992000"],["59774.07000000","1.46003000"],["59774.04000000","0.80190000"],["59774.03000000","0.00000000"],["59774.01000000","0.55345000"],["59773.30000000","0.05585000"],["59773.20000000","0.05592000"],["59772.81000000","0.21283000"],["59772.80000000","0.00009000"],["59772.00000000","0.02027000"],["59771.10000000","0.00009000"],["59770.51000000","0.63757000"],["59754.17000000","0.00334000"],["59753.17000000","0.00000000"],["59729.66000000","0.00000000"],["59729.61000000","0.00000000"],["59729.55000000","0.00000000"],["59666.46000000","0.00000000"],["53797.50000000","0.00105000"],["53797.00000000","0.00000000"],["47819.99000000","0.00000000"]],"a":[["59776.00000000","0.01318000"],["59788.11000000","0.02400000"],["59789.35000000","0.60300000"],["59798.98000000","0.00000000"],["60139.60000000","0.00010000"],["86395.28000000","0.00000000"]]}
{"e":"depthUpdate","E":1782785666614,"s":"BTCUSDT","U":96688020173,"u":96688020205,"b":[["59774.00000000","3.55918000"],["59773.30000000","0.05603000"],["59773.20000000","0.05610000"],["59772.00000000","0.02009000"],["59770.51000000","0.63739000"],["59707.47000000","0.23942000"],["59556.19000000","0.00000000"],["59525.28000000","0.02621000"],["53797.50000000","0.00126000"],["53797.00000000","0.00000000"]],"a":[["59775.00000000","0.18471000"],["59786.89000000","0.01400000"],["59789.10000000","0.00334000"],["59790.07000000","1.68283000"],["59846.62000000","0.46149000"],["59916.35000000","0.00000000"],["59922.33000000","0.00000000"],["59922.89000000","0.00000000"],["59928.31000000","0.00000000"],["59934.28000000","0.00000000"],["59940.26000000","0.00000000"],["59952.22000000","0.00000000"],["60283.37000000","0.00000000"],["60320.20000000","0.00000000"],["86884.50000000","0.00000000"]]}
{"e":"depthUpdate","E":1782785666714,"s":"BTCUSDT","U":96688020206,"u":96688020297,"b":[["59774.99000000","7.50260000"],["59774.08000000","0.34296000"],["59774.00000000","3.55650000"],["59767.10000000","0.60322000"],["59753.30000000","0.00000000"],["59736.92000000","0.00000000"],["59732.88000000","0.00000000"],["59729.77000000","0.00000000"],["59704.50000000","0.00000000"],["59697.15000000","0.01660000"],["59683.72000000","0.01660000"],["59670.29000000","0.01660000"],["53797.50000000","0.00168000"],["53797.00000000","0.00010000"]],"a":[["59775.00000000","0.03301000"],["59775.01000000","0.00090000"],["59775.61000000","0.00000000"],["59775.98000000","0.00020000"],["59775.99000000","0.00036000"],["59776.15000000","0.00000000"],["59776.16000000","0.00009000"],["59776.96000000","0.00000000"],["59777.80000000","0.00009000"],["59777.99000000","0.00009000"],["59778.49000000","0.00268000"],["59778.97000000","0.00036000"],["59779.00000000","0.00034000"],["59779.01000000","0.00009000"],["59779.39000000","0.12676000"],["59780.87000000","0.02000000"],["59781.00000000","0.00700000"],["59781.47000000","0.12000000"],["59781.98000000","0.00000000"],["59782.03000000","0.00000000"],["59782.04000000","0.00020000"],["59782.05000000","0.00000000"],["59784.00000000","0.02000000"],["59784.75000000","0.25887000"],["59784.76000000","0.00000000"],["59784.78000000","0.00000000"],["59784.79000000","0.01001000"],["59785.51000000","0.00000000"],["59785.95000000","0.05216000"],["59786.03000000","0.00400000"],["59787.00000000","0.00700000"],["59787.98000000","0.80192000"],["59787.99000000","0.00000000"],["59789.35000000","0.00000000"],["59790.59000000","0.00020000"],["59790.60000000","0.00000000"],["59799.99000000","0.01001000"],["59804.75000000","0.60284000"],["59832.25000000","0.00000000"],["59832.37000000","1.00513000"],["59838.31000000","3.34593000"],["59882.02000000","0.01500000"],["59887.99000000","0.02009000"],["59892.44000000","0.00000000"],["59893.97000000","0.02000000"],["59898.42000000","0.00000000"],["59899.95000000","0.02000000"],["59904.39000000","0.00000000"],["59905.93000000","0.02000000"],["59910.37000000","0.00000000"],["59911.90000000","0.02000000"],["59917.88000000","0.02000000"],["59923.86000000","0.02000000"],["59929.83000000","0.02000000"],["59941.79000000","0.02000000"],["60223.14000000","0.00000000"],["60440.31000000","0.15077000"],["79108.33000000","0.00076000"]]}
{"e":"depthUpdate","E":1782785666814,"s":"BTCUSDT","U":96688020298,"u":96688020447,"b":[["59774.99000000","7.62259000"],["59774.09000000","1.14468000"],["59774.08000000","0.00018000"],["59774.04000000","0.00018000"],["59774.00000000","3.55343000"],["59772.81000000","0.21265000"],["59772.04000000","0.00899000"],["59767.95000000","0.00000000"],["59767.45000000","0.00400000"],["59767.10000000","0.00000000"],["59766.75000000","0.01010000"],["59766.70000000","0.01000000"],["59766.15000000","0.02000000"],["59766.08000000","0.02000000"],["59764.38000000","0.01000000"],["59763.80000000","0.01000000"],["59763.78000000","0.01000000"],["59763.43000000","0.01400000"],["59763.21000000","0.02000000"],["59763.13000000","0.02000000"],["59763.03000000","0.17977000"],["59760.23000000","0.00000000"],["59759.93000000","0.00000000"],["59759.15000000","0.00000000"],["59757.10000000","0.00000000"],["59756.98000000","0.00000000"],["59756.64000000","0.00000000"],["59752.08000000","0.60337000"],["59751.07000000","0.00050000"],["59734.10000000","0.00000000"],["59732.77000000","0.00000000"],["59730.21000000","0.00000000"],["59625.94000000","0.01023000"],["59622.57000000","0.00000000"],["59616.30000000","0.10064000"],["59530.46000000","0.00094000"],["59521.30000000","0.00000000"],["53797.50000000","0.00210000"],["53797.49000000","0.00011000"],["53797.00000000","0.00000000"]],"a":[["59775.00000000","0.03318000"],["59775.01000000","0.00081000"],["59775.99000000","0.00018000"],["59776.17000000","0.06651000"],["59778.35000000","0.01066000"],["59778.49000000","0.00000000"],["59778.96000000","0.00020000"],["59778.97000000","0.00018000"],["59779.07000000","0.00000000"],["59779.16000000","0.06642000"],["59779.28000000","0.00009000"],["59779.29000000","0.08042000"],["59779.39000000","0.09191000"],["59779.98000000","0.00000000"],["59780.47000000","0.01000000"],["59780.70000000","0.00000000"],["59781.00000000","0.00300000"],["59781.46000000","0.00591000"],["59781.90000000","0.05226000"],["59782.14000000","0.29551000"],["59783.05000000","0.05056000"],["59784.00000000","0.02009000"],["59784.73000000","0.05216000"],["59784.74000000","0.80172000"],["59784.75000000","0.00000000"],["59784.77000000","0.00000000"],["59786.03000000","0.00000000"],["59786.50000000","0.00000000"],["59786.93000000","0.00000000"],["59787.00000000","0.00709000"],["59787.61000000","0.00000000"],["59787.90000000","0.00400000"],["59787.97000000","0.00009000"],["59788.49000000","0.00000000"],["59789.95000000","0.00000000"],["59789.98000000","1.38305000"],["59790.63000000","0.01675000"],["59790.64000000","0.00009000"],["59791.03000000","0.23748000"],["59792.20000000","0.00000000"],["59793.33000000","0.00400000"],["59794.57000000","0.00000000"],["59794.72000000","0.05592000"],["59795.84000000","0.00000000"],["59795.99000000","0.14431000"],["59798.08000000","0.09197000"],["59809.50000000","0.00400000"],["59811.00000000","0.00309000"],["59820.70000000","0.00000000"],["59821.30000000","0.00009000"],["59821.35000000","0.00000000"],["59832.37000000","0.00000000"],["59833.19000000","0.00000000"],["59833.70000000","0.00000000"],["59833.71000000","1.00513000"],["59846.62000000","0.00000000"],["59857.70000000","0.00000000"],["59874.19000000","0.00000000"],["59881.56000000","0.02621000"],["59900.86000000","0.10016000"],["59941.89000000","0.00009000"],["59944.87000000","0.00009000"],["60079.86000000","0.00009000"],["60500.76000000","0.17772000"],["87373.73000000","0.00000000"]]}
{"e":"depthUpdate","E":1782785666914,"s":"BTCUSDT","U":96688020448,"u":96688020514,"b":[["59774.99000000","7.65378000"],["59774.09000000","1.14486000"],["59774.08000000","0.00000000"],["59774.07000000","1.46003000"],["59774.04000000","0.00000000"],["59773.30000000","0.00018000"],["59773.20000000","0.00027000"],["59772.81000000","0.21283000"],["59760.63000000","0.00000000"],["59759.20000000","0.00000000"],["59757.36000000","0.00000000"],["59756.91000000","0.00000000"],["59756.36000000","0.00000000"],["59748.51000000","0.80651000"],["59739.13000000","1.68427000"],["59728.50000000","0.05582000"],["59727.14000000","0.00000000"],["59713.95000000","0.01660000"],["59707.47000000","0.00000000"],["59670.29000000","0.00000000"],["53797.50000000","0.00252000"],["53797.49000000","0.00000000"]],"a":[["59775.00000000","0.03273000"],["59778.35000000","0.01066000"],["59779.16000000","0.06651000"],["59779.28000000","0.00000000"],["59779.29000000","0.00018000"],["59782.13000000","0.01001000"],["59794.22000000","1.48771000"],["59833.71000000","0.00000000"],["59834.22000000","0.30394000"],["59834.23000000","1.00513000"],["59883.00000000","0.00000000"],["59889.12000000","0.02621000"],["87862.95000000","0.00000000"]]}
{"e":"depthUpdate","E":1782785667014,"s":"BTCUSDT","U":96688020515,"u":96688020557,"b":[["59774.99000000","7.65387000"],["59774.10000000","0.05583000"],["59774.01000000","0.55336000"],["59774.00000000","3.55334000"],["59773.99000000","0.00000000"],["59773.30000000","0.00000000"],["59773.20000000","0.00009000"],["59772.04000000","0.00917000"],["59772.00000000","0.02027000"],["59760.52000000","0.24759000"],["59759.53000000","0.00000000"],["59759.32000000","0.00000000"],["59758.44000000","0.80172000"],["59757.08000000","0.00000000"],["59756.12000000","0.00000000"],["53797.50000000","0.00294000"]],"a":[["59779.16000000","0.06651000"],["59779.29000000","0.00000000"],["59779.39000000","0.09209000"],["59783.45000000","0.00000000"],["59784.44000000","0.00018000"],["59813.82000000","0.00009000"],["59834.22000000","0.00000000"],["59834.23000000","0.00000000"],["59834.24000000","0.00000000"],["59834.39000000","1.00513000"],["59881.65000000","0.00000000"],["59944.87000000","0.00000000"],["79899.41000000","0.00010000"]]}
{"e":"depthUpdate","E":1782785667114,"s":"BTCUSDT","U":96688020558,"u":96688020579,"b":[["59774.99000000","7.65405000"],["59772.00000000","0.02009000"],["53797.50000000","0.00315000"],["53797.00000000","0.00000000"]],"a":[["59775.00000000","0.03282000"],["59775.01000000","0.00099000"],["59776.17000000","0.06660000"],["59778.69000000","0.00009000"],["59778.70000000","0.08042000"],["59781.00000000","0.00309000"],["59811.00000000","0.00300000"],["60079.86000000","0.00000000"],["60561.27000000","0.20949000"],["88126.17000000","0.00000000"]]}
{"e":"depthUpdate","E":1782785667214,"s":"BTCUSDT","U":96688020580,"u":96688020597,"b":[["59774.99000000","7.65569000"],["59774.10000000","0.05601000"],["59774.00000000","3.55324000"],["53797.50000000","0.00357000"]],"a":[["59775.00000000","0.03271000"],["59775.01000000","0.00116000"],["59775.02000000","0.00017000"],["59778.35000000","0.00000000"],["59779.55000000","0.00000000"],["59781.00000000","0.00300000"],["59811.00000000","0.00309000"],["60079.86000000","0.00009000"]]}
{"e":"depthUpdate","E":1782785667314,"s":"BTCUSDT","U":96688020598,"u":96688020610,"b":[["59691.32000000","0.00020000"],["53797.50000000","0.00399000"],["50000.00000000","604.02933000"]],"a":[["59775.61000000","0.00009000"],["59778.00000000","0.01318000"],["59821.44000000","0.08436000"],["60311.97000000","0.00000000"],["88126.22000000","0.00000000"]]}
{"e":"depthUpdate","E":1782785667414,"s":"BTCUSDT","U":96688020611,"u":96688020654,"b":[["59772.82000000","0.00020000"],["59772.81000000","0.21263000"],["59770.52000000","0.00020000"],["59770.01000000","0.00000000"],["59767.96000000","0.00000000"],["59766.04000000","0.00020000"],["59747.83000000","0.00000000"],["59736.54000000","1.85876000"],["59696.29000000","0.00000000"],["59616.30000000","0.00000000"],["53797.50000000","0.00441000"]],"a":[["59775.98000000","0.00000000"],["59776.16000000","0.00029000"],["59777.24000000","0.00009000"],["59778.69000000","0.00029000"],["59778.96000000","0.00000000"],["59780.37000000","0.00009000"],["59781.46000000","0.00611000"],["59782.04000000","0.00000000"],["59782.13000000","0.01021000"],["59783.99000000","0.00000000"],["59784.19000000","0.00020000"],["59784.73000000","0.05236000"],["59785.95000000","0.05236000"],["59786.92000000","0.00000000"],["59787.61000000","0.00020000"],["59787.97000000","0.00029000"],["59787.98000000","0.80172000"],["59788.48000000","0.00000000"],["59789.97000000","0.00020000"],["59790.06000000","0.00020000"],["59790.59000000","0.00000000"],["59791.02000000","0.00020000"],["59791.39000000","0.00000000"],["59791.91000000","0.00020000"],["59794.19000000","0.00000000"],["59794.22000000","1.48751000"],["59794.48000000","0.00020000"],["59889.12000000","0.00000000"],["59900.86000000","0.00000000"],["59935.39000000","0.02621000"],["60621.84000000","0.24698000"],["88352.17000000","0.00000000"]]}
{"e":"depthUpdate","E":1782785667514,"s":"BTCUSDT","U":96688020655,"u":96688020672,"b":[["59774.01000000","0.55837000"],["59731.78000000","0.00000000"],["59667.45000000","0.00020000"],["53797.50000000","0.00462000"],["47819.99000000","0.00000000"]],"a":[["59775.00000000","0.03271000"],["59775.01000000","0.00107000"]]}
{"e":"depthUpdate","E":1782785667614,"s":"BTCUSDT","U":96688020673,"u":96688020680,"b":[["59100.02000000","0.00846000"],["53797.50000000","0.00462000"]],"a":[["59804.89000000","0.00011000"],["79899.41000000","0.00065000"],["88357.32000000","0.00000000"]]}
{"e":"depthUpdate","E":1782785667714,"s":"BTCUSDT","U":96688020681,"u":96688020696,"b":[["59744.53000000","0.01660000"],["59731.78000000","0.00000000"],["59731.08000000","0.01660000"],["59697.15000000","0.00000000"],["59683.72000000","0.00000000"],["59666.44000000","0.00000000"],["53797.50000000","0.00441000"],["47819.00000000","0.00000000"]],"a":[["59782.12000000","0.01001000"],["59782.13000000","0.00020000"],["59935.39000000","0.00000000"],["59946.24000000","0.00000000"],["59982.11000000","0.00000000"],["86422.88000000","0.03782000"]]}
{"e":"depthUpdate","E":1782785667814,"s":"BTCUSDT","U":96688020697,"u":96688020709,"b":[["59731.78000000","0.00000000"],["59728.50000000","0.06582000"],["59727.14000000","0.01000000"],["53797.50000000","0.00462000"]],"a":[["59776.21000000","0.00009000"],["59858.69000000","0.00019000"],["59935.81000000","0.02000000"],["59971.67000000","0.02000000"],["86422.88000000","0.05673000"],["88919.29000000","0.00000000"]]}
{"e":"depthUpdate","E":1782785667914,"s":"BTCUSDT","U":96688020710,"u":96688020730,"b":[["59774.99000000","7.65624000"],["59758.62000000","0.00000000"],["59754.96000000","0.78000000"],["59743.04000000","0.00000000"],["59740.01000000","0.75486000"],["59707.47000000","0.23942000"],["59628.56000000","0.01022000"],["59625.94000000","0.00000000"],["53797.50000000","0.00462000"]],"a":[["59775.00000000","0.03290000"],["59808.60000000","0.78000000"],["80298.72000000","0.02508000"],["80698.41000000","0.00000000"],["89300.07000000","0.00006000"]]}
{"e":"depthUpdate","E":1782785668014,"s":"BTCUSDT","U":96688020731,"u":96688020740,"b":[["59760.52000000","0.24750000"],["53797.50000000","0.00462000"]],"a":[["59782.13000000","0.80192000"],["59784.44000000","0.00009000"],["59851.71000000","0.00000000"],["59882.64000000","0.00019000"],["79890.03000000","0.06363000"],["80298.72000000","0.05016000"]]}
{"e":"depthUpdate","E":1782785668114,"s":"BTCUSDT","U":96688020741,"u":96688020753,"b":[["59760.52000000","0.24759000"],["53797.50000000","0.00462000"]],"a":[["59782.12000000","0.56825000"],["59782.14000000","0.00000000"],["59783.05000000","0.00000000"],["59784.44000000","0.00018000"],["59785.95000000","0.00020000"],["79890.03000000","0.08484000"],["89447.64000000","0.00000000"]]}
{"e":"depthUpdate","E":1782785668214,"s":"BTCUSDT","U":96688020754,"u":96688020764,"b":[["59774.99000000","7.65634000"],["59666.81000000","0.02621000"],["59657.08000000","0.00000000"],["53797.50000000","0.00483000"]],"a":[["59781.00000000","0.00309000"],["59811.00000000","0.00300000"],["59881.63000000","0.00000000"],["60079.86000000","0.00000000"],["60312.96000000","0.00010000"]]}
{"e":"depthUpdate","E":1782785668314,"s":"BTCUSDT","U":96688020765,"u":96688020773,"b":[["53797.50000000","0.00483000"],["53797.00000000","0.00000000"],["50000.00000000","604.02933000"]],"a":[["89628.44000000","0.00000000"]]}
{"e":"depthUpdate","E":1782785668414,"s":"BTCUSDT","U":96688020774,"u":96688020794,"b":[["59774.99000000","7.65621000"],["59773.71000000","0.00928000"],["59766.04000000","0.00000000"],["59761.79000000","0.00020000"],["59751.07000000","0.00010000"],["54992.08000000","0.00019000"],["53797.50000000","0.00462000"]],"a":[["59782.12000000","0.56845000"],["59782.13000000","0.80172000"],["59784.19000000","0.00000000"],["59784.72000000","0.00020000"],["59785.96000000","0.43711000"],["59787.23000000","0.00020000"],["59787.61000000","0.00000000"],["59788.80000000","0.00020000"],["59791.02000000","0.00000000"],["59797.30000000","0.00020000"],["59805.95000000","0.00000000"],["89643.96000000","0.00000000"]]}
{"e":"depthUpdate","E":1782785668514,"s":"BTCUSDT","U":96688020795,"u":96688020819,"b":[["59774.00000000","3.55324000"],["59773.71000000","0.00946000"],["59772.04000000","0.00899000"],["59752.01000000","0.00000000"],["59734.09000000","0.00000000"],["59731.77000000","0.00000000"],["59666.81000000","0.00000000"],["53797.50000000","0.00462000"],["47819.99000000","0.00000000"]],"a":[]}
{"e":"depthUpdate","E":1782785668614,"s":"BTCUSDT","U":96688020820,"u":96688021190,"b":[["59776.16000000","8.83378000"],["59776.15000000","0.00035000"],["59776.14000000","0.00017000"],["59775.99000000","0.00000000"],["59775.98000000","0.00000000"],["59775.60000000","0.00000000"],["59775.59000000","0.00009000"],["59775.58000000","0.00000000"],["59775.01000000","0.00000000"],["59775.00000000","4.31021000"],["59774.99000000","4.40616000"],["59774.98000000","0.00000000"],["59774.97000000","0.00000000"],["59774.11000000","0.80172000"],["59774.10000000","0.05610000"],["59774.09000000","0.34314000"],["59774.07000000","0.00018000"],["59774.01000000","0.00548000"],["59774.00000000","0.03422000"],["59772.81000000","0.21245000"],["59764.20000000","0.19612000"],["59763.03000000","0.00000000"],["59754.95000000","0.00000000"],["59745.49000000","0.00000000"],["59744.53000000","0.00000000"],["59740.95000000","0.00000000"],["59731.08000000","0.00000000"],["59717.32000000","0.01660000"],["59714.99000000","0.00000000"],["59713.95000000","0.00000000"],["59705.84000000","0.01660000"],["59692.41000000","0.01660000"],["59678.98000000","0.00000000"],["59476.62000000","0.00000000"],["53797.50000000","0.00010000"],["53796.60000000","0.00000000"]],"a":[["59775.00000000","0.00000000"],["59775.01000000","0.00000000"],["59775.02000000","0.00000000"],["59775.59000000","0.00000000"],["59775.61000000","0.00000000"],["59775.99000000","0.00000000"],["59776.00000000","0.00000000"],["59776.01000000","0.00000000"],["59776.16000000","0.00000000"],["59776.17000000","0.06858000"],["59776.18000000","0.00081000"],["59776.46000000","0.00000000"],["59776.47000000","0.00000000"],["59777.99000000","0.03435000"],["59778.70000000","0.08060000"],["59778.96000000","0.00009000"],["59778.97000000","0.02018000"],["59779.39000000","0.09218000"],["59779.43000000","0.04467000"],["59780.00000000","0.01618000"],["59781.46000000","0.00611000"],["59781.90000000","0.00010000"],["59782.11000000","0.00000000"],["59782.12000000","0.28287000"],["59782.13000000","0.00000000"],["59784.20000000","0.00000000"],["59784.28000000","0.04735000"],["59784.73000000","0.05282000"],["59785.48000000","0.02174000"],["59794.72000000","0.00000000"],["59795.99000000","0.00000000"],["59805.00000000","0.00718000"],["59805.69000000","0.00009000"],["59807.00000000","0.01300000"],["59808.05000000","0.00000000"],["59821.44000000","0.00000000"],["80698.41000000","0.00055000"],["90453.37000000","0.00000000"]]}